Workbook
Name PerdaPot: #REF!

Sheet Orçamento
A1: Formação de Preço | D1: Relação de orçamentos de materiais | U1: Residencial
A2: MATERIAIS Kit Fotovoltaico | B2: =F3 -> 5871.08 | D2: Empresa | E2: Potência | F2: R$ | G2: R$/kW | H2: Placas | I2: Pot. Placas | J2: Estrutura | K2: Orientação | L2: Geração. SOLergo Anual (kWh) | M2: Geração. SOLergo Mensal (kWh) | U2: Ano | V2: Tarifa (R$/kWh) | W2: FioB (R$/kWh) | X2: FS | Y2: GD Eco Líquida (R$/kWh) | Z2: Economia Acum. | AA2: Gasto acum. | AC2: Ano | AD2: Potência Remanescente (%) | AE2: Degradação Anual (%) | AF2: Perda Acumulada (%) | AG2: Observação
A3: MÃO DE OBRA INSTALAÇÃO | B3: 1000 | D3: Maxsul | E3: 3.72 | F3: 5871.08 | G3: 2.74 | H3: 6 | I3: 590 | J3: Fibro | K3: L | L3: 4807.1 | M3: =L3/12 -> 400.59167 | U3: 2026 | V3: 1.1979 | W3: 0.2239 | X3: 30% | Y3: 1.1039 | Z3: =Y3*$B$35*12 -> 5306.5577 | AA3: =V3*$D$35*12 -> 5619.5792 | AC3: 0 | AD3: 100.00% | AE3: — | AF3: — | AG3: Início da operação
A4: MATERIAIS EXTRAS - INSTALAÇÃO | B4: 1300 | D4: IBS | E4: =H4*I4/1000 -> 7.44 | G4: =F4/(E4*1000) -> 0 | H4: 12 | I4: 620 | J4: Fibro | K4: L | L4: 8879.3 | M4: =L4/12 -> 739.94167 | Q4: Tipo de cliente | S4: Residencial | U4: 2027 | V4: 1.3057 | W4: 0.2441 | X4: 30% | Y4: 1.1775 | Z4: =Y4*$B$35*12+Z3 -> 10966.918 | AA4: =$B$35*V4*12+AA3 -> 11896.21 | AC4: 1 | AD4: 98.00% | AE4: 2.00% | AF4: 2.00% | AG4: LID - Light Induced Degradation
A5: FRETE + GUINCHO | D5: OIW | E5: =H5*I5/1000 -> 7.44 | G5: =F5/(E5*1000) -> 0 | H5: 12 | I5: 620 | J5: Fibro | K5: L | L5: 8879.3 | M5: =L5/12 -> 739.94167 | S5: Comercial | U5: 2028 | V5: 1.4232 | W5: 0.266 | X5: 30% | Y5: 1.2556 | Z5: =Y5*$B$35*12+Z4 -> 17002.713 | AA5: =$B$35*V5*12+AA4 -> 18737.674 | AC5: 2 | AD5: 97.45% | AE5: 0.55% | AF5: 2.55% | AG5: Degradação linear
A6: SATAPAS DE CONCRETO | D6: Foco | E6: =H6*I6/1000 -> 7.44 | G6: =F6/(E6*1000) -> 0 | H6: 12 | I6: 620 | J6: Fibro | K6: L | L6: 8879.3 | M6: =L6/12 -> 739.94167 | S6: Grupo A | U6: 2029 | V6: 1.5513 | W6: 0.29 | X6: 30% | Y6: 1.3686 | Z6: =Y6*$B$35*12+Z5 -> 23581.71 | AA6: =$B$35*V6*12+AA5 -> 26194.929 | AC6: 3 | AD6: 96.90% | AE6: 0.55% | AF6: 3.10%
A7: SUBESTAÇÃO DE ENERGIA | J7: Fibro | U7: 2030 | V7: 1.6909 | W7: 0.3161 | X7: 30% | Y7: 1.4918 | Z7: =Y7*$B$35*12+Z6 -> 30752.942 | AA7: =$B$35*V7*12+AA6 -> 34323.254 | AC7: 4 | AD7: 0.9635 | AE7: 0.0055 | AF7: 0.0365
A8: TERCEIRIZAÇÃO DE SERVIÇOS | Q8: Representantes | R8: João Victor Bagetti Fuchs | S8: 54 98110 8228 | U8: 2031 | V8: 1.8431 | W8: 0.3445 | X8: 30% | Y8: 1.6261 | Z8: =Y8*$B$35*12+Z7 -> 38569.767 | AA8: =$B$35*V8*12+AA7 -> 43183.22 | AC8: 5 | AD8: 0.958 | AE8: 0.0055 | AF8: 0.042
A9: ADMINISTRAÇÃO | B9: =MAX(15%*B15*IF(OR($C$15="",$C$15=0),1,1-$C$15),1500) -> 1813.9976 | E9: Geração Solergo Mensal | G9: =M3 -> 400.59167 | I9: 3204.7 | R9: Daniel Rotava | S9: 54 99646 8910 | U9: 2032 | V9: 2.009 | W9: 0.3755 | X9: 30% | Y9: 1.7724 | Z9: =Y9*$B$35*12+Z8 -> 47089.871 | AA9: =$B$35*V9*12+AA8 -> 52840.684 | AC9: 6 | AD9: 0.9525 | AE9: 0.0055 | AF9: 0.0475
A10: MKT, Combustível | B10: 150 | E10: Potencia do sistema | G10: =E4 -> 7.44 | U10: 2033 | V10: 2.1898 | W10: 0.4093 | X10: 30% | Y10: 1.9319 | Z10: =Y10*$B$35*12+Z9 -> 56376.707 | AA10: =$B$35*V10*12+AA9 -> 63367.272 | AC10: 7 | AD10: 0.947 | AE10: 0.0055 | AF10: 0.053
A11: RISCO DE ENGENHARIA | B11: 500 | E11: Numero de placas | G11: 4 | U11: 2034 | V11: 2.3869 | W11: 0.4462 | X11: 30% | Y11: 2.1058 | Z11: =Y11*$B$35*12+Z10 -> 66499.499 | AA11: =$B$35*V11*12+AA10 -> 74841.338 | AC11: 8 | AD11: 0.9415 | AE11: 0.0055 | AF11: 0.0585
A12: COMISSÃO | B12: =MAX(3%*B15*IF(OR($C$15="",$C$15=0),1,1-$C$15),600) -> 600 | C12: 0.03 | U12: 2035 | V12: 2.6017 | W12: 0.4863 | X12: 30% | Y12: 2.2953 | Z12: =Y12*$B$35*12+Z11 -> 77533.235 | AA12: =$B$35*V12*12+AA11 -> 87347.971 | AC12: 9 | AD12: 0.936 | AE12: 0.0055 | AF12: 0.064
A13: INDICAÇÃO | B13: =IF(C13="",0,C13*B15) -> 0 | C13: 0 | U13: 2036 | V13: 2.8359 | W13: 0.5301 | X13: 30% | Y13: 2.5019 | Z13: =Y13*$B$35*12+Z12 -> 89560.119 | AA13: =$B$35*V13*12+AA12 -> 100980.43 | AC13: 10 | AD13: 0.9305 | AE13: 0.0055 | AF13: 0.0695
A14: IMPOSTOS | B14: =16%*SUM(B3:B13) -> 858.23961 | C14: Desconto | Q14: Contato Representate | R14: =IF(B19="João Victor Bagetti Fuchs","(54) 98110 8228",IF(B19="Daniel Rotava","(54) 99646 8910","")) -> (54) 98110 8228 | U14: 2037 | V14: 3.0911 | W14: 0.5778 | X14: 30% | Y14: 2.7271 | Z14: =Y14*$B$35*12+Z13 -> 102669.56 | AA14: =$B$35*V14*12+AA13 -> 115839.65 | AC14: 11 | AD14: 0.925 | AE14: 0.0055 | AF14: 0.075
A15: TOTAL DO PROJETO | B15: =SUM(B2:B14) -> 12093.317 | C15: 0 | Q15: Com imposto produto | R15: =SUM(B2:B13)*1.095 -> 12302.41 | U15: 2038 | V15: 3.3693 | W15: 0.6298 | X15: 30% | Y15: 2.9725 | Z15: =Y15*$B$35*12+Z14 -> 116958.67 | AA15: =$B$35*V15*12+AA14 -> 132036.21 | AC15: 12 | AD15: 0.9195 | AE15: 0.0055 | AF15: 0.0805
A16: R$ / KW | B16: =B15/(G10*1000) -> 1.6254459 | E16: Mês | F16: Kwh | U16: 2039 | V16: 3.6725 | W16: 0.6865 | X16: 30% | Y16: 3.24 | Z16: =Y16*$B$35*12+Z15 -> 132533.67 | AA16: =$B$35*V16*12+AA15 -> 149690.29 | AC16: 13 | AD16: 0.914 | AE16: 0.0055 | AF16: 0.086
A17: Classe do Cliente | B17: Residencial | E17: Janeiro | F17: 1415.025 | U17: 2040 | V17: 4.003 | W17: 0.7483 | X17: 30% | Y17: 3.5316 | Z17: =Y17*$B$35*12+Z16 -> 149510.42 | AA17: =$B$35*V17*12+AA16 -> 168933.11 | AC17: 14 | AD17: 0.9085 | AE17: 0.0055 | AF17: 0.0915
A18: Nome do Cliente | B18: Cliente Delfos | E18: Fevereiro | F18: 1200 | U18: 2041 | V18: 4.3633 | W18: 0.8156 | X18: 30% | Y18: 3.8495 | Z18: =Y18*$B$35*12+Z17 -> 168015.36 | AA18: =$B$35*V18*12+AA17 -> 189907.93 | AC18: 15 | AD18: 0.903 | AE18: 0.0055 | AF18: 0.097
A19: Representante comercial | B19: João Victor Bagetti Fuchs | E19: Março | F19: 1192.713 | U19: 2042 | V19: 4.756 | W19: 0.889 | X19: 30% | Y19: 4.1959 | Z19: =Y19*$B$35*12+Z18 -> 188185.47 | AA19: =$B$35*V19*12+AA18 -> 212770.5 | AC19: 16 | AD19: 0.8975 | AE19: 0.0055 | AF19: 0.1025
A20: Descrição Painéis solares | B20: Placas fotovoltaicas Trina | E20: Abril | F20: 967.85 | U20: 2043 | V20: 5.184 | W20: 0.969 | X20: 30% | Y20: 4.5735 | Z20: =Y20*$B$35*12+Z19 -> 210170.74 | AA20: =$B$35*V20*12+AA19 -> 237690.5 | AC20: 17 | AD20: 0.892 | AE20: 0.0055 | AF20: 0.108
A21: Garantia Painéis | B21: 15 | E21: Maio | F21: 780.433 | U21: 2044 | V21: 5.6506 | W21: 1.0562 | X21: 30% | Y21: 4.9852 | Z21: =Y21*$B$35*12+Z20 -> 234135.09 | AA21: =$B$35*V21*12+AA20 -> 264853.5 | AC21: 18 | AD21: 0.8865 | AE21: 0.0055 | AF21: 0.1135
A22: Garantia de eficiência | B22: 0.875 | E22: Junho | F22: 638.11 | U22: 2045 | V22: 6.1592 | W22: 1.1513 | X22: 30% | Y22: 5.4339 | Z22: =Y22*$B$35*12+Z21 -> 260256.39 | AA22: =$B$35*V22*12+AA21 -> 294461.39 | AC22: 19 | AD22: 0.881 | AE22: 0.0055 | AF22: 0.119
A23: Tempo garantia Eficiência | B23: 30 | E23: Julho | F23: 747.714 | U23: 2046 | V23: =V22*1.09 -> 6.713528 | W23: =W22*1.09 -> 1.254917 | X23: 0.3 | Y23: 5.9229 | Z23: =Y23*$B$35*12+Z22 -> 288728.37 | AA23: =$B$35*V23*12+AA22 -> 326733.99 | AC23: 20 | AD23: =AD22*0.9938 -> 0.8755378 | AE23: 0.0055 | AF23: =AF22*AF21/AF20 -> 0.12506019
A24: Descrição Inversor | B24: Solis | E24: Agosto | F24: 930.39 | U24: 2047 | V24: 7.3177 | W24: 1.3678 | X24: 30% | Y24: 6.456 | Z24: =Y24*$B$35*12+Z23 -> 319763 | AA24: =$B$35*V24*12+AA23 -> 361910.91 | AC24: 21 | AD24: 0.87 | AE24: 0.0055 | AF24: 0.13
A25: Quantidade de inversores | B25: 1 | E25: Setembro | F25: 918.95 | U25: 2048 | V25: 7.9763 | W25: 1.4909 | X25: 30% | Y25: 7.037 | Z25: =Y25*$B$35*12+Z24 -> 353590.57 | AA25: =$B$35*V25*12+AA24 -> 400253.78 | AC25: 22 | AD25: 0.8645 | AE25: 0.0055 | AF25: 0.1355
A26: Garantia Inversor | B26: 10 | E26: Outubro | F26: 1176.758 | U26: 2049 | V26: 8.6942 | W26: 1.6251 | X26: 30% | Y26: 7.6704 | Z26: =Y26*$B$35*12+Z25 -> 390462.95 | AA26: =$B$35*V26*12+AA25 -> 442047.67 | AC26: 23 | AD26: 0.859 | AE26: 0.0055 | AF26: 0.141
A27: Estruturas de fixação | B27: Estruturas fibrocimento | E27: Novembro | F27: 1368.626 | U27: 2050 | V27: 9.4766 | W27: 1.7714 | X27: 30% | Y27: 8.3606 | Z27: =Y27*$B$35*12+Z26 -> 430653.19 | AA27: =$B$35*V27*12+AA26 -> 487602.63 | AC27: 24 | AD27: 0.8535 | AE27: 0.0055 | AF27: 0.1465
A28: Data da proposta | B28: 20 de julho de 2026 | E28: Dezembro | F28: 1500 | U28: 2051 | V28: 10.3295 | W28: 1.9308 | X28: 30% | Y28: 9.1131 | Z28: =Y28*$B$35*12+Z27 -> 474460.77 | AA28: =$B$35*V28*12+AA27 -> 537257.57 | AC28: 25 | AD28: 0.848 | AE28: 0.0055 | AF28: 0.152 | AG28: Fim da garantia linear (≥80% exigido)
A29: Código FINAME | B29: - | AC29: ▶ RESUMO
A30: Consumo Atual do Cliente | U30: Comercial | AC30: Potência no Ano 25 | AG30: 84.80%
A31: Potência do Sistema (kwp) | B31: =G10 -> 7.44 | U31: Ano | V31: Tarifa (R$/kWh) | W31: FioB (R$/kWh) | X31: FS | Y31: GD Eco Líquida (R$/kWh) | AC31: Degradação Média Anual (excluindo Ano 1) | AG31: 0.55%
A32: Numero de Placas | B32: =G11 -> 4 | U32: 2026 | V32: 1.1979 | W32: 0.2239 | X32: 70% | Y32: 1.1576 | Z32: =Y32*$B$35*12 -> 5564.699 | AA32: =V32*$D$35*12 -> 5619.5792 | AC32: Perda Total Acumulada em 25 anos | AG32: 15.20%
A33: Area total | B33: =B32*(1.14*2.38)+(1.14*2.38*2) -> 16.2792 | D33: Parcelas | E33: Taxa mensal de juros | F33: Número de parcelas | U33: 2027 | V33: 1.3057 | W33: 0.2441 | X33: 70% | Y33: 1.2508 | Z33: =Y33*$B$35*12+Z32 -> 11577.42 | AA33: =$B$35*V33*12+AA32 -> 11896.21 | AC33: Vida Útil Estimada (até 80%) | AG33: ~26.3 anos
A34: Valor a vista | B34: =B15 -> 12093.317 | C34: Cartão de credito | D34: =PMT(E34, 18, -R15, 0, 0) -> 849.00195 | E34: 0.0239 | F34: 18 | G34: Stone | U34: 2028 | V34: 1.4232 | W34: 0.266 | X34: 70% | Y34: 1.3514 | Z34: =Y34*$B$35*12+Z33 -> 18073.735 | AA34: =$B$35*V34*12+AA33 -> 18737.674
A35: Geração em Kwh/mês | B35: =G9 -> 400.59167 | C35: Banco 1 | D35: =PMT(E35,F35,-(B34+F37)) -> 390.93269 | E35: 0.019 | F35: 60 | G35: Cresol | U35: 2029 | V35: 1.5513 | W35: 0.29 | X35: 70% | Y35: 1.473 | Z35: =Y35*$B$35*12+Z34 -> 25154.593 | AA35: =$B$35*V35*12+AA34 -> 26194.929
A36: Geração anual estimada (kwh) | B36: =B35*12 -> 4807.1 | C36: Banco 2 | D36: =PMT(E36,F35,-(B34+F37)) -> 308.89345 | E36: 0.0099 | G36: Caixa | U36: 2030 | V36: 1.6909 | W36: 0.3161 | X36: 70% | Y36: 1.6056 | Z36: =Y36*$B$35*12+Z35 -> 32872.873 | AA36: =$B$35*V36*12+AA35 -> 34323.254
A37: Economia em 1 mês | B37: =IF(B17="Residencial",Z3/12,IF(B17="Comercial",Z32/12,"")) -> 442.21314 | E37: IOF total | F37: =B34*(0.0038+0.000082*30*F35) -> 1830.9282 | U37: 2031 | V37: 1.8431 | W37: 0.3445 | X37: 70% | Y37: 1.7501 | Z37: =Y37*$B$35*12+Z36 -> 41285.778 | AA37: =$B$35*V37*12+AA36 -> 43183.22
A38: Economia em 1 anos | B38: =IF(B17="Residencial",Z3,IF($B$17="Comercial",Z32,"")) -> 5306.5577 | U38: 2032 | V38: 2.009 | W38: 0.3755 | X38: 70% | Y38: 1.9076 | Z38: =Y38*$B$35*12+Z37 -> 50455.802 | AA38: =$B$35*V38*12+AA37 -> 52840.684
A39: Economia em 5 anos | B39: =IF(B17="Residencial",Z8*AD8,IF(B17="Comercial",Z37*AD8,"")) -> 36949.837 | U39: 2033 | V39: 2.1898 | W39: 0.4093 | X39: 70% | Y39: 2.0793 | Z39: =Y39*$B$35*12+Z38 -> 60451.205 | AA39: =$B$35*V39*12+AA38 -> 63367.272
A40: Economia em 10 anos | B40: =IF(B17="Residencial",Z13*AD13,IF(B17="Comercial",Z42*AD13,"")) -> 83335.69 | U40: 2034 | V40: 2.3869 | W40: 0.4462 | X40: 70% | Y40: 2.2664 | Z40: =Y40*$B$35*12+Z39 -> 71346.017 | AA40: =$B$35*V40*12+AA39 -> 74841.338
...

Sheet Base
A1: NOME_CLIENTE | B1: NOME_REPRESENTANTE | C1: CONTATO_REPRESENTANTE | D1: Data_Proposta | E1: Descricao_paineis | F1: descricao_inversores | G1: QTD_Paineis | H1: QTD_Inversores | I1: Estrutura_Fix | J1: Potencia | K1: Area | L1: Producao_anual | M1: Producao_mensal | N1: Janeiro | O1: Fevereiro | P1: Março | Q1: Abril | R1: Maio | S1: Junho | T1: Julho | U1: Agosto | V1: Setembro | W1: Outubro | X1: Novembro | Y1: Dezembro | Z1: Economiaem1mes | AA1: Economiaem1anos | AB1: Economiaem5anos | AC1: Economiaem10anos | AD1: Economiaem25anos | AE1: Valorgastoem1ano | AF1: Valorgasto5anos | AG1: Valorgasto10anos | AH1: Valorgastoem25anos | AI1: Retornodoinvestimento | AJ1: Contacomsolar | AK1: Valor_total | AL1: Payback | AM1: ParcelaB1 | AN1: ParcelaB2 | AO1: Contahoje | AP1: Nparcelas | AQ1: nparcelascartao | AR1: juroscartao | AS1: valorparcelacartao | AT1: GarantiaPaineis | AU1: Garantiainversor | AV1: garantiadesenpenho | AW1: desempenho | AX1: CodFiname
A2: =Orçamento!B18 -> Cliente Delfos | B2: =Orçamento!B19 -> João Victor Bagetti Fuchs | C2: =Orçamento!R14 -> (54) 98110 8228 | D2: =Orçamento!B28 -> 20 de julho de 2026 | E2: =Orçamento!B20 -> Placas fotovoltaicas Trina | F2: =Orçamento!B24 -> Solis | G2: =Orçamento!B32 -> 4 | H2: =Orçamento!B25 -> 1 | I2: =Orçamento!B27 -> Estruturas fibrocimento | J2: =Orçamento!B31 -> 7.44 | K2: =Orçamento!B33 -> 16.2792 | L2: =Orçamento!B36 -> 4807.1 | M2: =Orçamento!B35 -> 400.59167 | N2: =Orçamento!F17 -> 1415.025 | O2: =Orçamento!F18 -> 1200 | P2: =Orçamento!F19 -> 1192.713 | Q2: =Orçamento!F20 -> 967.85 | R2: =Orçamento!F21 -> 780.433 | S2: =Orçamento!F22 -> 638.11 | T2: =Orçamento!F23 -> 747.714 | U2: =Orçamento!F24 -> 930.39 | V2: =Orçamento!F25 -> 918.95 | W2: =Orçamento!F26 -> 1176.758 | X2: =Orçamento!F26 -> 1176.758 | Y2: =Orçamento!F28 -> 1500 | Z2: =Orçamento!B37 -> 442.21314 | AA2: =Orçamento!B38 -> 5306.5577 | AB2: =Orçamento!B39 -> 36949.837 | AC2: =Orçamento!B40 -> 83335.69 | AD2: =Orçamento!B41 -> 402342.73 | AE2: =Orçamento!B43 -> 5619.5792 | AF2: =Orçamento!B44 -> 43183.22 | AG2: =Orçamento!B45 -> 100980.43 | AH2: =Orçamento!B46 -> 537257.57 | AI2: =Orçamento!B47 -> 25 meses | AJ2: =Orçamento!B48 -> 89.890612 | AK2: =Orçamento!B15 -> 12093.317 | AL2: =Orçamento!B47 -> 25 meses | AM2: =Orçamento!D35 -> 390.93269 | AN2: =Orçamento!D36 -> 308.89345 | AO2: =Orçamento!B42 -> 479.86876 | AP2: =Orçamento!F35 -> 60 | AQ2: =Orçamento!F34 -> 18 | AR2: =Orçamento!E34 -> 0.0239 | AS2: =Orçamento!D34 -> 849.00195 | AT2: =Orçamento!B21 -> 15 | AU2: =Orçamento!B26 -> 10 | AV2: =Orçamento!B23 -> 30 | AW2: =Orçamento!B22 -> 0.875 | AX2: =Orçamento!B29 -> -
